2021-03-14 20:31:27,429 - 
Downloading Utility Log. 
Log started.

Move log to Impt Logs if required as only the 10 most recent logs are kept.

2021-03-14 20:31:31,803 - Command: dl -youtube https://www.youtube.com/watch?v=wQPgM-9LatM
2021-03-14 20:31:31,803 - youtube link
2021-03-14 20:31:32,309 - Scraping for id: wQPgM-9LatM
2021-03-14 20:31:32,436 - HTTPSConnectionPool(host='youtu.be', port=443): Max retries exceeded with url: /wQPgM-9LatM (Caused by NewConnectionError('<urllib3.connection.HTTPSConnection object at 0x053A3B98>: Failed to establish a new connection: [Errno 11001] getaddrinfo failed'))
Traceback (most recent call last):
  File "C:\Users\sanpee\AppData\Local\Programs\Python\Python38-32\lib\site-packages\urllib3\connection.py", line 159, in _new_conn
    conn = connection.create_connection(
  File "C:\Users\sanpee\AppData\Local\Programs\Python\Python38-32\lib\site-packages\urllib3\util\connection.py", line 61, in create_connection
    for res in socket.getaddrinfo(host, port, family, socket.SOCK_STREAM):
  File "C:\Users\sanpee\AppData\Local\Programs\Python\Python38-32\lib\socket.py", line 918, in getaddrinfo
    for res in _socket.getaddrinfo(host, port, family, type, proto, flags):
socket.gaierror: [Errno 11001] getaddrinfo failed

During handling of the above exception, another exception occurred:

Traceback (most recent call last):
  File "C:\Users\sanpee\AppData\Local\Programs\Python\Python38-32\lib\site-packages\urllib3\connectionpool.py", line 670, in urlopen
    httplib_response = self._make_request(
  File "C:\Users\sanpee\AppData\Local\Programs\Python\Python38-32\lib\site-packages\urllib3\connectionpool.py", line 381, in _make_request
    self._validate_conn(conn)
  File "C:\Users\sanpee\AppData\Local\Programs\Python\Python38-32\lib\site-packages\urllib3\connectionpool.py", line 976, in _validate_conn
    conn.connect()
  File "C:\Users\sanpee\AppData\Local\Programs\Python\Python38-32\lib\site-packages\urllib3\connection.py", line 308, in connect
    conn = self._new_conn()
  File "C:\Users\sanpee\AppData\Local\Programs\Python\Python38-32\lib\site-packages\urllib3\connection.py", line 171, in _new_conn
    raise NewConnectionError(
urllib3.exceptions.NewConnectionError: <urllib3.connection.HTTPSConnection object at 0x0534FC88>: Failed to establish a new connection: [Errno 11001] getaddrinfo failed

During handling of the above exception, another exception occurred:

Traceback (most recent call last):
  File "C:\Users\sanpee\AppData\Local\Programs\Python\Python38-32\lib\site-packages\requests\adapters.py", line 439, in send
    resp = conn.urlopen(
  File "C:\Users\sanpee\AppData\Local\Programs\Python\Python38-32\lib\site-packages\urllib3\connectionpool.py", line 724, in urlopen
    retries = retries.increment(
  File "C:\Users\sanpee\AppData\Local\Programs\Python\Python38-32\lib\site-packages\urllib3\util\retry.py", line 439, in increment
    raise MaxRetryError(_pool, url, error or ResponseError(cause))
urllib3.exceptions.MaxRetryError: HTTPSConnectionPool(host='youtu.be', port=443): Max retries exceeded with url: /wQPgM-9LatM (Caused by NewConnectionError('<urllib3.connection.HTTPSConnection object at 0x0534FC88>: Failed to establish a new connection: [Errno 11001] getaddrinfo failed'))

During handling of the above exception, another exception occurred:

Traceback (most recent call last):
  File "C:\Utilities\Scripts\url-dl-v2\extractors\youtube.py", line 290, in extract_video_info
    test = scrape_yt_link(url)
  File "C:\Utilities\Scripts\url-dl-v2\extractors\youtube.py", line 247, in scrape_yt_link
    response = requests.get(url)
  File "C:\Users\sanpee\AppData\Local\Programs\Python\Python38-32\lib\site-packages\requests\api.py", line 76, in get
    return request('get', url, params=params, **kwargs)
  File "C:\Users\sanpee\AppData\Local\Programs\Python\Python38-32\lib\site-packages\requests\api.py", line 61, in request
    return session.request(method=method, url=url, **kwargs)
  File "C:\Users\sanpee\AppData\Local\Programs\Python\Python38-32\lib\site-packages\requests\sessions.py", line 530, in request
    resp = self.send(prep, **send_kwargs)
  File "C:\Users\sanpee\AppData\Local\Programs\Python\Python38-32\lib\site-packages\requests\sessions.py", line 643, in send
    r = adapter.send(request, **kwargs)
  File "C:\Users\sanpee\AppData\Local\Programs\Python\Python38-32\lib\site-packages\requests\adapters.py", line 516, in send
    raise ConnectionError(e, request=request)
requests.exceptions.ConnectionError: HTTPSConnectionPool(host='youtu.be', port=443): Max retries exceeded with url: /wQPgM-9LatM (Caused by NewConnectionError('<urllib3.connection.HTTPSConnection object at 0x0534FC88>: Failed to establish a new connection: [Errno 11001] getaddrinfo failed'))

During handling of the above exception, another exception occurred:

Traceback (most recent call last):
  File "C:\Users\sanpee\AppData\Local\Programs\Python\Python38-32\lib\site-packages\urllib3\connection.py", line 159, in _new_conn
    conn = connection.create_connection(
  File "C:\Users\sanpee\AppData\Local\Programs\Python\Python38-32\lib\site-packages\urllib3\util\connection.py", line 61, in create_connection
    for res in socket.getaddrinfo(host, port, family, socket.SOCK_STREAM):
  File "C:\Users\sanpee\AppData\Local\Programs\Python\Python38-32\lib\socket.py", line 918, in getaddrinfo
    for res in _socket.getaddrinfo(host, port, family, type, proto, flags):
socket.gaierror: [Errno 11001] getaddrinfo failed

During handling of the above exception, another exception occurred:

Traceback (most recent call last):
  File "C:\Users\sanpee\AppData\Local\Programs\Python\Python38-32\lib\site-packages\urllib3\connectionpool.py", line 670, in urlopen
    httplib_response = self._make_request(
  File "C:\Users\sanpee\AppData\Local\Programs\Python\Python38-32\lib\site-packages\urllib3\connectionpool.py", line 381, in _make_request
    self._validate_conn(conn)
  File "C:\Users\sanpee\AppData\Local\Programs\Python\Python38-32\lib\site-packages\urllib3\connectionpool.py", line 976, in _validate_conn
    conn.connect()
  File "C:\Users\sanpee\AppData\Local\Programs\Python\Python38-32\lib\site-packages\urllib3\connection.py", line 308, in connect
    conn = self._new_conn()
  File "C:\Users\sanpee\AppData\Local\Programs\Python\Python38-32\lib\site-packages\urllib3\connection.py", line 171, in _new_conn
    raise NewConnectionError(
urllib3.exceptions.NewConnectionError: <urllib3.connection.HTTPSConnection object at 0x053831F0>: Failed to establish a new connection: [Errno 11001] getaddrinfo failed

During handling of the above exception, another exception occurred:

Traceback (most recent call last):
  File "C:\Users\sanpee\AppData\Local\Programs\Python\Python38-32\lib\site-packages\requests\adapters.py", line 439, in send
    resp = conn.urlopen(
  File "C:\Users\sanpee\AppData\Local\Programs\Python\Python38-32\lib\site-packages\urllib3\connectionpool.py", line 724, in urlopen
    retries = retries.increment(
  File "C:\Users\sanpee\AppData\Local\Programs\Python\Python38-32\lib\site-packages\urllib3\util\retry.py", line 439, in increment
    raise MaxRetryError(_pool, url, error or ResponseError(cause))
urllib3.exceptions.MaxRetryError: HTTPSConnectionPool(host='youtu.be', port=443): Max retries exceeded with url: /wQPgM-9LatM (Caused by NewConnectionError('<urllib3.connection.HTTPSConnection object at 0x053831F0>: Failed to establish a new connection: [Errno 11001] getaddrinfo failed'))

During handling of the above exception, another exception occurred:

Traceback (most recent call last):
  File "C:\Utilities\Scripts\url-dl-v2\extractors\youtube.py", line 293, in extract_video_info
    test = scrape_yt_link(url)
  File "C:\Utilities\Scripts\url-dl-v2\extractors\youtube.py", line 247, in scrape_yt_link
    response = requests.get(url)
  File "C:\Users\sanpee\AppData\Local\Programs\Python\Python38-32\lib\site-packages\requests\api.py", line 76, in get
    return request('get', url, params=params, **kwargs)
  File "C:\Users\sanpee\AppData\Local\Programs\Python\Python38-32\lib\site-packages\requests\api.py", line 61, in request
    return session.request(method=method, url=url, **kwargs)
  File "C:\Users\sanpee\AppData\Local\Programs\Python\Python38-32\lib\site-packages\requests\sessions.py", line 530, in request
    resp = self.send(prep, **send_kwargs)
  File "C:\Users\sanpee\AppData\Local\Programs\Python\Python38-32\lib\site-packages\requests\sessions.py", line 643, in send
    r = adapter.send(request, **kwargs)
  File "C:\Users\sanpee\AppData\Local\Programs\Python\Python38-32\lib\site-packages\requests\adapters.py", line 516, in send
    raise ConnectionError(e, request=request)
requests.exceptions.ConnectionError: HTTPSConnectionPool(host='youtu.be', port=443): Max retries exceeded with url: /wQPgM-9LatM (Caused by NewConnectionError('<urllib3.connection.HTTPSConnection object at 0x053831F0>: Failed to establish a new connection: [Errno 11001] getaddrinfo failed'))

During handling of the above exception, another exception occurred:

Traceback (most recent call last):
  File "C:\Users\sanpee\AppData\Local\Programs\Python\Python38-32\lib\site-packages\urllib3\connection.py", line 159, in _new_conn
    conn = connection.create_connection(
  File "C:\Users\sanpee\AppData\Local\Programs\Python\Python38-32\lib\site-packages\urllib3\util\connection.py", line 61, in create_connection
    for res in socket.getaddrinfo(host, port, family, socket.SOCK_STREAM):
  File "C:\Users\sanpee\AppData\Local\Programs\Python\Python38-32\lib\socket.py", line 918, in getaddrinfo
    for res in _socket.getaddrinfo(host, port, family, type, proto, flags):
socket.gaierror: [Errno 11001] getaddrinfo failed

During handling of the above exception, another exception occurred:

Traceback (most recent call last):
  File "C:\Users\sanpee\AppData\Local\Programs\Python\Python38-32\lib\site-packages\urllib3\connectionpool.py", line 670, in urlopen
    httplib_response = self._make_request(
  File "C:\Users\sanpee\AppData\Local\Programs\Python\Python38-32\lib\site-packages\urllib3\connectionpool.py", line 381, in _make_request
    self._validate_conn(conn)
  File "C:\Users\sanpee\AppData\Local\Programs\Python\Python38-32\lib\site-packages\urllib3\connectionpool.py", line 976, in _validate_conn
    conn.connect()
  File "C:\Users\sanpee\AppData\Local\Programs\Python\Python38-32\lib\site-packages\urllib3\connection.py", line 308, in connect
    conn = self._new_conn()
  File "C:\Users\sanpee\AppData\Local\Programs\Python\Python38-32\lib\site-packages\urllib3\connection.py", line 171, in _new_conn
    raise NewConnectionError(
urllib3.exceptions.NewConnectionError: <urllib3.connection.HTTPSConnection object at 0x05383610>: Failed to establish a new connection: [Errno 11001] getaddrinfo failed

During handling of the above exception, another exception occurred:

Traceback (most recent call last):
  File "C:\Users\sanpee\AppData\Local\Programs\Python\Python38-32\lib\site-packages\requests\adapters.py", line 439, in send
    resp = conn.urlopen(
  File "C:\Users\sanpee\AppData\Local\Programs\Python\Python38-32\lib\site-packages\urllib3\connectionpool.py", line 724, in urlopen
    retries = retries.increment(
  File "C:\Users\sanpee\AppData\Local\Programs\Python\Python38-32\lib\site-packages\urllib3\util\retry.py", line 439, in increment
    raise MaxRetryError(_pool, url, error or ResponseError(cause))
urllib3.exceptions.MaxRetryError: HTTPSConnectionPool(host='youtu.be', port=443): Max retries exceeded with url: /wQPgM-9LatM (Caused by NewConnectionError('<urllib3.connection.HTTPSConnection object at 0x05383610>: Failed to establish a new connection: [Errno 11001] getaddrinfo failed'))

During handling of the above exception, another exception occurred:

Traceback (most recent call last):
  File "C:\Utilities\Scripts\url-dl-v2\extractors\youtube.py", line 296, in extract_video_info
    test = scrape_yt_link(url)
  File "C:\Utilities\Scripts\url-dl-v2\extractors\youtube.py", line 247, in scrape_yt_link
    response = requests.get(url)
  File "C:\Users\sanpee\AppData\Local\Programs\Python\Python38-32\lib\site-packages\requests\api.py", line 76, in get
    return request('get', url, params=params, **kwargs)
  File "C:\Users\sanpee\AppData\Local\Programs\Python\Python38-32\lib\site-packages\requests\api.py", line 61, in request
    return session.request(method=method, url=url, **kwargs)
  File "C:\Users\sanpee\AppData\Local\Programs\Python\Python38-32\lib\site-packages\requests\sessions.py", line 530, in request
    resp = self.send(prep, **send_kwargs)
  File "C:\Users\sanpee\AppData\Local\Programs\Python\Python38-32\lib\site-packages\requests\sessions.py", line 643, in send
    r = adapter.send(request, **kwargs)
  File "C:\Users\sanpee\AppData\Local\Programs\Python\Python38-32\lib\site-packages\requests\adapters.py", line 516, in send
    raise ConnectionError(e, request=request)
requests.exceptions.ConnectionError: HTTPSConnectionPool(host='youtu.be', port=443): Max retries exceeded with url: /wQPgM-9LatM (Caused by NewConnectionError('<urllib3.connection.HTTPSConnection object at 0x05383610>: Failed to establish a new connection: [Errno 11001] getaddrinfo failed'))

During handling of the above exception, another exception occurred:

Traceback (most recent call last):
  File "C:\Users\sanpee\AppData\Local\Programs\Python\Python38-32\lib\site-packages\urllib3\connection.py", line 159, in _new_conn
    conn = connection.create_connection(
  File "C:\Users\sanpee\AppData\Local\Programs\Python\Python38-32\lib\site-packages\urllib3\util\connection.py", line 61, in create_connection
    for res in socket.getaddrinfo(host, port, family, socket.SOCK_STREAM):
  File "C:\Users\sanpee\AppData\Local\Programs\Python\Python38-32\lib\socket.py", line 918, in getaddrinfo
    for res in _socket.getaddrinfo(host, port, family, type, proto, flags):
socket.gaierror: [Errno 11001] getaddrinfo failed

During handling of the above exception, another exception occurred:

Traceback (most recent call last):
  File "C:\Users\sanpee\AppData\Local\Programs\Python\Python38-32\lib\site-packages\urllib3\connectionpool.py", line 670, in urlopen
    httplib_response = self._make_request(
  File "C:\Users\sanpee\AppData\Local\Programs\Python\Python38-32\lib\site-packages\urllib3\connectionpool.py", line 381, in _make_request
    self._validate_conn(conn)
  File "C:\Users\sanpee\AppData\Local\Programs\Python\Python38-32\lib\site-packages\urllib3\connectionpool.py", line 976, in _validate_conn
    conn.connect()
  File "C:\Users\sanpee\AppData\Local\Programs\Python\Python38-32\lib\site-packages\urllib3\connection.py", line 308, in connect
    conn = self._new_conn()
  File "C:\Users\sanpee\AppData\Local\Programs\Python\Python38-32\lib\site-packages\urllib3\connection.py", line 171, in _new_conn
    raise NewConnectionError(
urllib3.exceptions.NewConnectionError: <urllib3.connection.HTTPSConnection object at 0x05383A30>: Failed to establish a new connection: [Errno 11001] getaddrinfo failed

During handling of the above exception, another exception occurred:

Traceback (most recent call last):
  File "C:\Users\sanpee\AppData\Local\Programs\Python\Python38-32\lib\site-packages\requests\adapters.py", line 439, in send
    resp = conn.urlopen(
  File "C:\Users\sanpee\AppData\Local\Programs\Python\Python38-32\lib\site-packages\urllib3\connectionpool.py", line 724, in urlopen
    retries = retries.increment(
  File "C:\Users\sanpee\AppData\Local\Programs\Python\Python38-32\lib\site-packages\urllib3\util\retry.py", line 439, in increment
    raise MaxRetryError(_pool, url, error or ResponseError(cause))
urllib3.exceptions.MaxRetryError: HTTPSConnectionPool(host='youtu.be', port=443): Max retries exceeded with url: /wQPgM-9LatM (Caused by NewConnectionError('<urllib3.connection.HTTPSConnection object at 0x05383A30>: Failed to establish a new connection: [Errno 11001] getaddrinfo failed'))

During handling of the above exception, another exception occurred:

Traceback (most recent call last):
  File "C:\Utilities\Scripts\url-dl-v2\extractors\youtube.py", line 227, in youtube_extractor
    sub_object["video_info"], sub_object["streams"] = extract_video_info(sub_object["id"])
  File "C:\Utilities\Scripts\url-dl-v2\extractors\youtube.py", line 298, in extract_video_info
    test = scrape_yt_link(url)
  File "C:\Utilities\Scripts\url-dl-v2\extractors\youtube.py", line 247, in scrape_yt_link
    response = requests.get(url)
  File "C:\Users\sanpee\AppData\Local\Programs\Python\Python38-32\lib\site-packages\requests\api.py", line 76, in get
    return request('get', url, params=params, **kwargs)
  File "C:\Users\sanpee\AppData\Local\Programs\Python\Python38-32\lib\site-packages\requests\api.py", line 61, in request
    return session.request(method=method, url=url, **kwargs)
  File "C:\Users\sanpee\AppData\Local\Programs\Python\Python38-32\lib\site-packages\requests\sessions.py", line 530, in request
    resp = self.send(prep, **send_kwargs)
  File "C:\Users\sanpee\AppData\Local\Programs\Python\Python38-32\lib\site-packages\requests\sessions.py", line 643, in send
    r = adapter.send(request, **kwargs)
  File "C:\Users\sanpee\AppData\Local\Programs\Python\Python38-32\lib\site-packages\requests\adapters.py", line 516, in send
    raise ConnectionError(e, request=request)
requests.exceptions.ConnectionError: HTTPSConnectionPool(host='youtu.be', port=443): Max retries exceeded with url: /wQPgM-9LatM (Caused by NewConnectionError('<urllib3.connection.HTTPSConnection object at 0x05383A30>: Failed to establish a new connection: [Errno 11001] getaddrinfo failed'))

During handling of the above exception, another exception occurred:

Traceback (most recent call last):
  File "C:\Users\sanpee\AppData\Local\Programs\Python\Python38-32\lib\site-packages\urllib3\connection.py", line 159, in _new_conn
    conn = connection.create_connection(
  File "C:\Users\sanpee\AppData\Local\Programs\Python\Python38-32\lib\site-packages\urllib3\util\connection.py", line 61, in create_connection
    for res in socket.getaddrinfo(host, port, family, socket.SOCK_STREAM):
  File "C:\Users\sanpee\AppData\Local\Programs\Python\Python38-32\lib\socket.py", line 918, in getaddrinfo
    for res in _socket.getaddrinfo(host, port, family, type, proto, flags):
socket.gaierror: [Errno 11001] getaddrinfo failed

During handling of the above exception, another exception occurred:

Traceback (most recent call last):
  File "C:\Users\sanpee\AppData\Local\Programs\Python\Python38-32\lib\site-packages\urllib3\connectionpool.py", line 670, in urlopen
    httplib_response = self._make_request(
  File "C:\Users\sanpee\AppData\Local\Programs\Python\Python38-32\lib\site-packages\urllib3\connectionpool.py", line 381, in _make_request
    self._validate_conn(conn)
  File "C:\Users\sanpee\AppData\Local\Programs\Python\Python38-32\lib\site-packages\urllib3\connectionpool.py", line 976, in _validate_conn
    conn.connect()
  File "C:\Users\sanpee\AppData\Local\Programs\Python\Python38-32\lib\site-packages\urllib3\connection.py", line 308, in connect
    conn = self._new_conn()
  File "C:\Users\sanpee\AppData\Local\Programs\Python\Python38-32\lib\site-packages\urllib3\connection.py", line 171, in _new_conn
    raise NewConnectionError(
urllib3.exceptions.NewConnectionError: <urllib3.connection.HTTPSConnection object at 0x05383E50>: Failed to establish a new connection: [Errno 11001] getaddrinfo failed

During handling of the above exception, another exception occurred:

Traceback (most recent call last):
  File "C:\Users\sanpee\AppData\Local\Programs\Python\Python38-32\lib\site-packages\requests\adapters.py", line 439, in send
    resp = conn.urlopen(
  File "C:\Users\sanpee\AppData\Local\Programs\Python\Python38-32\lib\site-packages\urllib3\connectionpool.py", line 724, in urlopen
    retries = retries.increment(
  File "C:\Users\sanpee\AppData\Local\Programs\Python\Python38-32\lib\site-packages\urllib3\util\retry.py", line 439, in increment
    raise MaxRetryError(_pool, url, error or ResponseError(cause))
urllib3.exceptions.MaxRetryError: HTTPSConnectionPool(host='youtu.be', port=443): Max retries exceeded with url: /wQPgM-9LatM (Caused by NewConnectionError('<urllib3.connection.HTTPSConnection object at 0x05383E50>: Failed to establish a new connection: [Errno 11001] getaddrinfo failed'))

During handling of the above exception, another exception occurred:

Traceback (most recent call last):
  File "C:\Utilities\Scripts\url-dl-v2\extractors\youtube.py", line 290, in extract_video_info
    test = scrape_yt_link(url)
  File "C:\Utilities\Scripts\url-dl-v2\extractors\youtube.py", line 247, in scrape_yt_link
    response = requests.get(url)
  File "C:\Users\sanpee\AppData\Local\Programs\Python\Python38-32\lib\site-packages\requests\api.py", line 76, in get
    return request('get', url, params=params, **kwargs)
  File "C:\Users\sanpee\AppData\Local\Programs\Python\Python38-32\lib\site-packages\requests\api.py", line 61, in request
    return session.request(method=method, url=url, **kwargs)
  File "C:\Users\sanpee\AppData\Local\Programs\Python\Python38-32\lib\site-packages\requests\sessions.py", line 530, in request
    resp = self.send(prep, **send_kwargs)
  File "C:\Users\sanpee\AppData\Local\Programs\Python\Python38-32\lib\site-packages\requests\sessions.py", line 643, in send
    r = adapter.send(request, **kwargs)
  File "C:\Users\sanpee\AppData\Local\Programs\Python\Python38-32\lib\site-packages\requests\adapters.py", line 516, in send
    raise ConnectionError(e, request=request)
requests.exceptions.ConnectionError: HTTPSConnectionPool(host='youtu.be', port=443): Max retries exceeded with url: /wQPgM-9LatM (Caused by NewConnectionError('<urllib3.connection.HTTPSConnection object at 0x05383E50>: Failed to establish a new connection: [Errno 11001] getaddrinfo failed'))

During handling of the above exception, another exception occurred:

Traceback (most recent call last):
  File "C:\Users\sanpee\AppData\Local\Programs\Python\Python38-32\lib\site-packages\urllib3\connection.py", line 159, in _new_conn
    conn = connection.create_connection(
  File "C:\Users\sanpee\AppData\Local\Programs\Python\Python38-32\lib\site-packages\urllib3\util\connection.py", line 61, in create_connection
    for res in socket.getaddrinfo(host, port, family, socket.SOCK_STREAM):
  File "C:\Users\sanpee\AppData\Local\Programs\Python\Python38-32\lib\socket.py", line 918, in getaddrinfo
    for res in _socket.getaddrinfo(host, port, family, type, proto, flags):
socket.gaierror: [Errno 11001] getaddrinfo failed

During handling of the above exception, another exception occurred:

Traceback (most recent call last):
  File "C:\Users\sanpee\AppData\Local\Programs\Python\Python38-32\lib\site-packages\urllib3\connectionpool.py", line 670, in urlopen
    httplib_response = self._make_request(
  File "C:\Users\sanpee\AppData\Local\Programs\Python\Python38-32\lib\site-packages\urllib3\connectionpool.py", line 381, in _make_request
    self._validate_conn(conn)
  File "C:\Users\sanpee\AppData\Local\Programs\Python\Python38-32\lib\site-packages\urllib3\connectionpool.py", line 976, in _validate_conn
    conn.connect()
  File "C:\Users\sanpee\AppData\Local\Programs\Python\Python38-32\lib\site-packages\urllib3\connection.py", line 308, in connect
    conn = self._new_conn()
  File "C:\Users\sanpee\AppData\Local\Programs\Python\Python38-32\lib\site-packages\urllib3\connection.py", line 171, in _new_conn
    raise NewConnectionError(
urllib3.exceptions.NewConnectionError: <urllib3.connection.HTTPSConnection object at 0x053932B0>: Failed to establish a new connection: [Errno 11001] getaddrinfo failed

During handling of the above exception, another exception occurred:

Traceback (most recent call last):
  File "C:\Users\sanpee\AppData\Local\Programs\Python\Python38-32\lib\site-packages\requests\adapters.py", line 439, in send
    resp = conn.urlopen(
  File "C:\Users\sanpee\AppData\Local\Programs\Python\Python38-32\lib\site-packages\urllib3\connectionpool.py", line 724, in urlopen
    retries = retries.increment(
  File "C:\Users\sanpee\AppData\Local\Programs\Python\Python38-32\lib\site-packages\urllib3\util\retry.py", line 439, in increment
    raise MaxRetryError(_pool, url, error or ResponseError(cause))
urllib3.exceptions.MaxRetryError: HTTPSConnectionPool(host='youtu.be', port=443): Max retries exceeded with url: /wQPgM-9LatM (Caused by NewConnectionError('<urllib3.connection.HTTPSConnection object at 0x053932B0>: Failed to establish a new connection: [Errno 11001] getaddrinfo failed'))

During handling of the above exception, another exception occurred:

Traceback (most recent call last):
  File "C:\Utilities\Scripts\url-dl-v2\extractors\youtube.py", line 293, in extract_video_info
    test = scrape_yt_link(url)
  File "C:\Utilities\Scripts\url-dl-v2\extractors\youtube.py", line 247, in scrape_yt_link
    response = requests.get(url)
  File "C:\Users\sanpee\AppData\Local\Programs\Python\Python38-32\lib\site-packages\requests\api.py", line 76, in get
    return request('get', url, params=params, **kwargs)
  File "C:\Users\sanpee\AppData\Local\Programs\Python\Python38-32\lib\site-packages\requests\api.py", line 61, in request
    return session.request(method=method, url=url, **kwargs)
  File "C:\Users\sanpee\AppData\Local\Programs\Python\Python38-32\lib\site-packages\requests\sessions.py", line 530, in request
    resp = self.send(prep, **send_kwargs)
  File "C:\Users\sanpee\AppData\Local\Programs\Python\Python38-32\lib\site-packages\requests\sessions.py", line 643, in send
    r = adapter.send(request, **kwargs)
  File "C:\Users\sanpee\AppData\Local\Programs\Python\Python38-32\lib\site-packages\requests\adapters.py", line 516, in send
    raise ConnectionError(e, request=request)
requests.exceptions.ConnectionError: HTTPSConnectionPool(host='youtu.be', port=443): Max retries exceeded with url: /wQPgM-9LatM (Caused by NewConnectionError('<urllib3.connection.HTTPSConnection object at 0x053932B0>: Failed to establish a new connection: [Errno 11001] getaddrinfo failed'))

During handling of the above exception, another exception occurred:

Traceback (most recent call last):
  File "C:\Users\sanpee\AppData\Local\Programs\Python\Python38-32\lib\site-packages\urllib3\connection.py", line 159, in _new_conn
    conn = connection.create_connection(
  File "C:\Users\sanpee\AppData\Local\Programs\Python\Python38-32\lib\site-packages\urllib3\util\connection.py", line 61, in create_connection
    for res in socket.getaddrinfo(host, port, family, socket.SOCK_STREAM):
  File "C:\Users\sanpee\AppData\Local\Programs\Python\Python38-32\lib\socket.py", line 918, in getaddrinfo
    for res in _socket.getaddrinfo(host, port, family, type, proto, flags):
socket.gaierror: [Errno 11001] getaddrinfo failed

During handling of the above exception, another exception occurred:

Traceback (most recent call last):
  File "C:\Users\sanpee\AppData\Local\Programs\Python\Python38-32\lib\site-packages\urllib3\connectionpool.py", line 670, in urlopen
    httplib_response = self._make_request(
  File "C:\Users\sanpee\AppData\Local\Programs\Python\Python38-32\lib\site-packages\urllib3\connectionpool.py", line 381, in _make_request
    self._validate_conn(conn)
  File "C:\Users\sanpee\AppData\Local\Programs\Python\Python38-32\lib\site-packages\urllib3\connectionpool.py", line 976, in _validate_conn
    conn.connect()
  File "C:\Users\sanpee\AppData\Local\Programs\Python\Python38-32\lib\site-packages\urllib3\connection.py", line 308, in connect
    conn = self._new_conn()
  File "C:\Users\sanpee\AppData\Local\Programs\Python\Python38-32\lib\site-packages\urllib3\connection.py", line 171, in _new_conn
    raise NewConnectionError(
urllib3.exceptions.NewConnectionError: <urllib3.connection.HTTPSConnection object at 0x053936D0>: Failed to establish a new connection: [Errno 11001] getaddrinfo failed

During handling of the above exception, another exception occurred:

Traceback (most recent call last):
  File "C:\Users\sanpee\AppData\Local\Programs\Python\Python38-32\lib\site-packages\requests\adapters.py", line 439, in send
    resp = conn.urlopen(
  File "C:\Users\sanpee\AppData\Local\Programs\Python\Python38-32\lib\site-packages\urllib3\connectionpool.py", line 724, in urlopen
    retries = retries.increment(
  File "C:\Users\sanpee\AppData\Local\Programs\Python\Python38-32\lib\site-packages\urllib3\util\retry.py", line 439, in increment
    raise MaxRetryError(_pool, url, error or ResponseError(cause))
urllib3.exceptions.MaxRetryError: HTTPSConnectionPool(host='youtu.be', port=443): Max retries exceeded with url: /wQPgM-9LatM (Caused by NewConnectionError('<urllib3.connection.HTTPSConnection object at 0x053936D0>: Failed to establish a new connection: [Errno 11001] getaddrinfo failed'))

During handling of the above exception, another exception occurred:

Traceback (most recent call last):
  File "C:\Utilities\Scripts\url-dl-v2\extractors\youtube.py", line 296, in extract_video_info
    test = scrape_yt_link(url)
  File "C:\Utilities\Scripts\url-dl-v2\extractors\youtube.py", line 247, in scrape_yt_link
    response = requests.get(url)
  File "C:\Users\sanpee\AppData\Local\Programs\Python\Python38-32\lib\site-packages\requests\api.py", line 76, in get
    return request('get', url, params=params, **kwargs)
  File "C:\Users\sanpee\AppData\Local\Programs\Python\Python38-32\lib\site-packages\requests\api.py", line 61, in request
    return session.request(method=method, url=url, **kwargs)
  File "C:\Users\sanpee\AppData\Local\Programs\Python\Python38-32\lib\site-packages\requests\sessions.py", line 530, in request
    resp = self.send(prep, **send_kwargs)
  File "C:\Users\sanpee\AppData\Local\Programs\Python\Python38-32\lib\site-packages\requests\sessions.py", line 643, in send
    r = adapter.send(request, **kwargs)
  File "C:\Users\sanpee\AppData\Local\Programs\Python\Python38-32\lib\site-packages\requests\adapters.py", line 516, in send
    raise ConnectionError(e, request=request)
requests.exceptions.ConnectionError: HTTPSConnectionPool(host='youtu.be', port=443): Max retries exceeded with url: /wQPgM-9LatM (Caused by NewConnectionError('<urllib3.connection.HTTPSConnection object at 0x053936D0>: Failed to establish a new connection: [Errno 11001] getaddrinfo failed'))

During handling of the above exception, another exception occurred:

Traceback (most recent call last):
  File "C:\Users\sanpee\AppData\Local\Programs\Python\Python38-32\lib\site-packages\urllib3\connection.py", line 159, in _new_conn
    conn = connection.create_connection(
  File "C:\Users\sanpee\AppData\Local\Programs\Python\Python38-32\lib\site-packages\urllib3\util\connection.py", line 61, in create_connection
    for res in socket.getaddrinfo(host, port, family, socket.SOCK_STREAM):
  File "C:\Users\sanpee\AppData\Local\Programs\Python\Python38-32\lib\socket.py", line 918, in getaddrinfo
    for res in _socket.getaddrinfo(host, port, family, type, proto, flags):
socket.gaierror: [Errno 11001] getaddrinfo failed

During handling of the above exception, another exception occurred:

Traceback (most recent call last):
  File "C:\Users\sanpee\AppData\Local\Programs\Python\Python38-32\lib\site-packages\urllib3\connectionpool.py", line 670, in urlopen
    httplib_response = self._make_request(
  File "C:\Users\sanpee\AppData\Local\Programs\Python\Python38-32\lib\site-packages\urllib3\connectionpool.py", line 381, in _make_request
    self._validate_conn(conn)
  File "C:\Users\sanpee\AppData\Local\Programs\Python\Python38-32\lib\site-packages\urllib3\connectionpool.py", line 976, in _validate_conn
    conn.connect()
  File "C:\Users\sanpee\AppData\Local\Programs\Python\Python38-32\lib\site-packages\urllib3\connection.py", line 308, in connect
    conn = self._new_conn()
  File "C:\Users\sanpee\AppData\Local\Programs\Python\Python38-32\lib\site-packages\urllib3\connection.py", line 171, in _new_conn
    raise NewConnectionError(
urllib3.exceptions.NewConnectionError: <urllib3.connection.HTTPSConnection object at 0x05393AF0>: Failed to establish a new connection: [Errno 11001] getaddrinfo failed

During handling of the above exception, another exception occurred:

Traceback (most recent call last):
  File "C:\Users\sanpee\AppData\Local\Programs\Python\Python38-32\lib\site-packages\requests\adapters.py", line 439, in send
    resp = conn.urlopen(
  File "C:\Users\sanpee\AppData\Local\Programs\Python\Python38-32\lib\site-packages\urllib3\connectionpool.py", line 724, in urlopen
    retries = retries.increment(
  File "C:\Users\sanpee\AppData\Local\Programs\Python\Python38-32\lib\site-packages\urllib3\util\retry.py", line 439, in increment
    raise MaxRetryError(_pool, url, error or ResponseError(cause))
urllib3.exceptions.MaxRetryError: HTTPSConnectionPool(host='youtu.be', port=443): Max retries exceeded with url: /wQPgM-9LatM (Caused by NewConnectionError('<urllib3.connection.HTTPSConnection object at 0x05393AF0>: Failed to establish a new connection: [Errno 11001] getaddrinfo failed'))

During handling of the above exception, another exception occurred:

Traceback (most recent call last):
  File "C:\Utilities\Scripts\url-dl-v2\extractors\youtube.py", line 231, in youtube_extractor
    sub_object["video_info"], sub_object["streams"] = extract_video_info(sub_object["id"])
  File "C:\Utilities\Scripts\url-dl-v2\extractors\youtube.py", line 298, in extract_video_info
    test = scrape_yt_link(url)
  File "C:\Utilities\Scripts\url-dl-v2\extractors\youtube.py", line 247, in scrape_yt_link
    response = requests.get(url)
  File "C:\Users\sanpee\AppData\Local\Programs\Python\Python38-32\lib\site-packages\requests\api.py", line 76, in get
    return request('get', url, params=params, **kwargs)
  File "C:\Users\sanpee\AppData\Local\Programs\Python\Python38-32\lib\site-packages\requests\api.py", line 61, in request
    return session.request(method=method, url=url, **kwargs)
  File "C:\Users\sanpee\AppData\Local\Programs\Python\Python38-32\lib\site-packages\requests\sessions.py", line 530, in request
    resp = self.send(prep, **send_kwargs)
  File "C:\Users\sanpee\AppData\Local\Programs\Python\Python38-32\lib\site-packages\requests\sessions.py", line 643, in send
    r = adapter.send(request, **kwargs)
  File "C:\Users\sanpee\AppData\Local\Programs\Python\Python38-32\lib\site-packages\requests\adapters.py", line 516, in send
    raise ConnectionError(e, request=request)
requests.exceptions.ConnectionError: HTTPSConnectionPool(host='youtu.be', port=443): Max retries exceeded with url: /wQPgM-9LatM (Caused by NewConnectionError('<urllib3.connection.HTTPSConnection object at 0x05393AF0>: Failed to establish a new connection: [Errno 11001] getaddrinfo failed'))

During handling of the above exception, another exception occurred:

Traceback (most recent call last):
  File "C:\Users\sanpee\AppData\Local\Programs\Python\Python38-32\lib\site-packages\urllib3\connection.py", line 159, in _new_conn
    conn = connection.create_connection(
  File "C:\Users\sanpee\AppData\Local\Programs\Python\Python38-32\lib\site-packages\urllib3\util\connection.py", line 61, in create_connection
    for res in socket.getaddrinfo(host, port, family, socket.SOCK_STREAM):
  File "C:\Users\sanpee\AppData\Local\Programs\Python\Python38-32\lib\socket.py", line 918, in getaddrinfo
    for res in _socket.getaddrinfo(host, port, family, type, proto, flags):
socket.gaierror: [Errno 11001] getaddrinfo failed

During handling of the above exception, another exception occurred:

Traceback (most recent call last):
  File "C:\Users\sanpee\AppData\Local\Programs\Python\Python38-32\lib\site-packages\urllib3\connectionpool.py", line 670, in urlopen
    httplib_response = self._make_request(
  File "C:\Users\sanpee\AppData\Local\Programs\Python\Python38-32\lib\site-packages\urllib3\connectionpool.py", line 381, in _make_request
    self._validate_conn(conn)
  File "C:\Users\sanpee\AppData\Local\Programs\Python\Python38-32\lib\site-packages\urllib3\connectionpool.py", line 976, in _validate_conn
    conn.connect()
  File "C:\Users\sanpee\AppData\Local\Programs\Python\Python38-32\lib\site-packages\urllib3\connection.py", line 308, in connect
    conn = self._new_conn()
  File "C:\Users\sanpee\AppData\Local\Programs\Python\Python38-32\lib\site-packages\urllib3\connection.py", line 171, in _new_conn
    raise NewConnectionError(
urllib3.exceptions.NewConnectionError: <urllib3.connection.HTTPSConnection object at 0x05393F10>: Failed to establish a new connection: [Errno 11001] getaddrinfo failed

During handling of the above exception, another exception occurred:

Traceback (most recent call last):
  File "C:\Users\sanpee\AppData\Local\Programs\Python\Python38-32\lib\site-packages\requests\adapters.py", line 439, in send
    resp = conn.urlopen(
  File "C:\Users\sanpee\AppData\Local\Programs\Python\Python38-32\lib\site-packages\urllib3\connectionpool.py", line 724, in urlopen
    retries = retries.increment(
  File "C:\Users\sanpee\AppData\Local\Programs\Python\Python38-32\lib\site-packages\urllib3\util\retry.py", line 439, in increment
    raise MaxRetryError(_pool, url, error or ResponseError(cause))
urllib3.exceptions.MaxRetryError: HTTPSConnectionPool(host='youtu.be', port=443): Max retries exceeded with url: /wQPgM-9LatM (Caused by NewConnectionError('<urllib3.connection.HTTPSConnection object at 0x05393F10>: Failed to establish a new connection: [Errno 11001] getaddrinfo failed'))

During handling of the above exception, another exception occurred:

Traceback (most recent call last):
  File "C:\Utilities\Scripts\url-dl-v2\extractors\youtube.py", line 290, in extract_video_info
    test = scrape_yt_link(url)
  File "C:\Utilities\Scripts\url-dl-v2\extractors\youtube.py", line 247, in scrape_yt_link
    response = requests.get(url)
  File "C:\Users\sanpee\AppData\Local\Programs\Python\Python38-32\lib\site-packages\requests\api.py", line 76, in get
    return request('get', url, params=params, **kwargs)
  File "C:\Users\sanpee\AppData\Local\Programs\Python\Python38-32\lib\site-packages\requests\api.py", line 61, in request
    return session.request(method=method, url=url, **kwargs)
  File "C:\Users\sanpee\AppData\Local\Programs\Python\Python38-32\lib\site-packages\requests\sessions.py", line 530, in request
    resp = self.send(prep, **send_kwargs)
  File "C:\Users\sanpee\AppData\Local\Programs\Python\Python38-32\lib\site-packages\requests\sessions.py", line 643, in send
    r = adapter.send(request, **kwargs)
  File "C:\Users\sanpee\AppData\Local\Programs\Python\Python38-32\lib\site-packages\requests\adapters.py", line 516, in send
    raise ConnectionError(e, request=request)
requests.exceptions.ConnectionError: HTTPSConnectionPool(host='youtu.be', port=443): Max retries exceeded with url: /wQPgM-9LatM (Caused by NewConnectionError('<urllib3.connection.HTTPSConnection object at 0x05393F10>: Failed to establish a new connection: [Errno 11001] getaddrinfo failed'))

During handling of the above exception, another exception occurred:

Traceback (most recent call last):
  File "C:\Users\sanpee\AppData\Local\Programs\Python\Python38-32\lib\site-packages\urllib3\connection.py", line 159, in _new_conn
    conn = connection.create_connection(
  File "C:\Users\sanpee\AppData\Local\Programs\Python\Python38-32\lib\site-packages\urllib3\util\connection.py", line 61, in create_connection
    for res in socket.getaddrinfo(host, port, family, socket.SOCK_STREAM):
  File "C:\Users\sanpee\AppData\Local\Programs\Python\Python38-32\lib\socket.py", line 918, in getaddrinfo
    for res in _socket.getaddrinfo(host, port, family, type, proto, flags):
socket.gaierror: [Errno 11001] getaddrinfo failed

During handling of the above exception, another exception occurred:

Traceback (most recent call last):
  File "C:\Users\sanpee\AppData\Local\Programs\Python\Python38-32\lib\site-packages\urllib3\connectionpool.py", line 670, in urlopen
    httplib_response = self._make_request(
  File "C:\Users\sanpee\AppData\Local\Programs\Python\Python38-32\lib\site-packages\urllib3\connectionpool.py", line 381, in _make_request
    self._validate_conn(conn)
  File "C:\Users\sanpee\AppData\Local\Programs\Python\Python38-32\lib\site-packages\urllib3\connectionpool.py", line 976, in _validate_conn
    conn.connect()
  File "C:\Users\sanpee\AppData\Local\Programs\Python\Python38-32\lib\site-packages\urllib3\connection.py", line 308, in connect
    conn = self._new_conn()
  File "C:\Users\sanpee\AppData\Local\Programs\Python\Python38-32\lib\site-packages\urllib3\connection.py", line 171, in _new_conn
    raise NewConnectionError(
urllib3.exceptions.NewConnectionError: <urllib3.connection.HTTPSConnection object at 0x053A3358>: Failed to establish a new connection: [Errno 11001] getaddrinfo failed

During handling of the above exception, another exception occurred:

Traceback (most recent call last):
  File "C:\Users\sanpee\AppData\Local\Programs\Python\Python38-32\lib\site-packages\requests\adapters.py", line 439, in send
    resp = conn.urlopen(
  File "C:\Users\sanpee\AppData\Local\Programs\Python\Python38-32\lib\site-packages\urllib3\connectionpool.py", line 724, in urlopen
    retries = retries.increment(
  File "C:\Users\sanpee\AppData\Local\Programs\Python\Python38-32\lib\site-packages\urllib3\util\retry.py", line 439, in increment
    raise MaxRetryError(_pool, url, error or ResponseError(cause))
urllib3.exceptions.MaxRetryError: HTTPSConnectionPool(host='youtu.be', port=443): Max retries exceeded with url: /wQPgM-9LatM (Caused by NewConnectionError('<urllib3.connection.HTTPSConnection object at 0x053A3358>: Failed to establish a new connection: [Errno 11001] getaddrinfo failed'))

During handling of the above exception, another exception occurred:

Traceback (most recent call last):
  File "C:\Utilities\Scripts\url-dl-v2\extractors\youtube.py", line 293, in extract_video_info
    test = scrape_yt_link(url)
  File "C:\Utilities\Scripts\url-dl-v2\extractors\youtube.py", line 247, in scrape_yt_link
    response = requests.get(url)
  File "C:\Users\sanpee\AppData\Local\Programs\Python\Python38-32\lib\site-packages\requests\api.py", line 76, in get
    return request('get', url, params=params, **kwargs)
  File "C:\Users\sanpee\AppData\Local\Programs\Python\Python38-32\lib\site-packages\requests\api.py", line 61, in request
    return session.request(method=method, url=url, **kwargs)
  File "C:\Users\sanpee\AppData\Local\Programs\Python\Python38-32\lib\site-packages\requests\sessions.py", line 530, in request
    resp = self.send(prep, **send_kwargs)
  File "C:\Users\sanpee\AppData\Local\Programs\Python\Python38-32\lib\site-packages\requests\sessions.py", line 643, in send
    r = adapter.send(request, **kwargs)
  File "C:\Users\sanpee\AppData\Local\Programs\Python\Python38-32\lib\site-packages\requests\adapters.py", line 516, in send
    raise ConnectionError(e, request=request)
requests.exceptions.ConnectionError: HTTPSConnectionPool(host='youtu.be', port=443): Max retries exceeded with url: /wQPgM-9LatM (Caused by NewConnectionError('<urllib3.connection.HTTPSConnection object at 0x053A3358>: Failed to establish a new connection: [Errno 11001] getaddrinfo failed'))

During handling of the above exception, another exception occurred:

Traceback (most recent call last):
  File "C:\Users\sanpee\AppData\Local\Programs\Python\Python38-32\lib\site-packages\urllib3\connection.py", line 159, in _new_conn
    conn = connection.create_connection(
  File "C:\Users\sanpee\AppData\Local\Programs\Python\Python38-32\lib\site-packages\urllib3\util\connection.py", line 61, in create_connection
    for res in socket.getaddrinfo(host, port, family, socket.SOCK_STREAM):
  File "C:\Users\sanpee\AppData\Local\Programs\Python\Python38-32\lib\socket.py", line 918, in getaddrinfo
    for res in _socket.getaddrinfo(host, port, family, type, proto, flags):
socket.gaierror: [Errno 11001] getaddrinfo failed

During handling of the above exception, another exception occurred:

Traceback (most recent call last):
  File "C:\Users\sanpee\AppData\Local\Programs\Python\Python38-32\lib\site-packages\urllib3\connectionpool.py", line 670, in urlopen
    httplib_response = self._make_request(
  File "C:\Users\sanpee\AppData\Local\Programs\Python\Python38-32\lib\site-packages\urllib3\connectionpool.py", line 381, in _make_request
    self._validate_conn(conn)
  File "C:\Users\sanpee\AppData\Local\Programs\Python\Python38-32\lib\site-packages\urllib3\connectionpool.py", line 976, in _validate_conn
    conn.connect()
  File "C:\Users\sanpee\AppData\Local\Programs\Python\Python38-32\lib\site-packages\urllib3\connection.py", line 308, in connect
    conn = self._new_conn()
  File "C:\Users\sanpee\AppData\Local\Programs\Python\Python38-32\lib\site-packages\urllib3\connection.py", line 171, in _new_conn
    raise NewConnectionError(
urllib3.exceptions.NewConnectionError: <urllib3.connection.HTTPSConnection object at 0x053A3778>: Failed to establish a new connection: [Errno 11001] getaddrinfo failed

During handling of the above exception, another exception occurred:

Traceback (most recent call last):
  File "C:\Users\sanpee\AppData\Local\Programs\Python\Python38-32\lib\site-packages\requests\adapters.py", line 439, in send
    resp = conn.urlopen(
  File "C:\Users\sanpee\AppData\Local\Programs\Python\Python38-32\lib\site-packages\urllib3\connectionpool.py", line 724, in urlopen
    retries = retries.increment(
  File "C:\Users\sanpee\AppData\Local\Programs\Python\Python38-32\lib\site-packages\urllib3\util\retry.py", line 439, in increment
    raise MaxRetryError(_pool, url, error or ResponseError(cause))
urllib3.exceptions.MaxRetryError: HTTPSConnectionPool(host='youtu.be', port=443): Max retries exceeded with url: /wQPgM-9LatM (Caused by NewConnectionError('<urllib3.connection.HTTPSConnection object at 0x053A3778>: Failed to establish a new connection: [Errno 11001] getaddrinfo failed'))

During handling of the above exception, another exception occurred:

Traceback (most recent call last):
  File "C:\Utilities\Scripts\url-dl-v2\extractors\youtube.py", line 296, in extract_video_info
    test = scrape_yt_link(url)
  File "C:\Utilities\Scripts\url-dl-v2\extractors\youtube.py", line 247, in scrape_yt_link
    response = requests.get(url)
  File "C:\Users\sanpee\AppData\Local\Programs\Python\Python38-32\lib\site-packages\requests\api.py", line 76, in get
    return request('get', url, params=params, **kwargs)
  File "C:\Users\sanpee\AppData\Local\Programs\Python\Python38-32\lib\site-packages\requests\api.py", line 61, in request
    return session.request(method=method, url=url, **kwargs)
  File "C:\Users\sanpee\AppData\Local\Programs\Python\Python38-32\lib\site-packages\requests\sessions.py", line 530, in request
    resp = self.send(prep, **send_kwargs)
  File "C:\Users\sanpee\AppData\Local\Programs\Python\Python38-32\lib\site-packages\requests\sessions.py", line 643, in send
    r = adapter.send(request, **kwargs)
  File "C:\Users\sanpee\AppData\Local\Programs\Python\Python38-32\lib\site-packages\requests\adapters.py", line 516, in send
    raise ConnectionError(e, request=request)
requests.exceptions.ConnectionError: HTTPSConnectionPool(host='youtu.be', port=443): Max retries exceeded with url: /wQPgM-9LatM (Caused by NewConnectionError('<urllib3.connection.HTTPSConnection object at 0x053A3778>: Failed to establish a new connection: [Errno 11001] getaddrinfo failed'))

During handling of the above exception, another exception occurred:

Traceback (most recent call last):
  File "C:\Users\sanpee\AppData\Local\Programs\Python\Python38-32\lib\site-packages\urllib3\connection.py", line 159, in _new_conn
    conn = connection.create_connection(
  File "C:\Users\sanpee\AppData\Local\Programs\Python\Python38-32\lib\site-packages\urllib3\util\connection.py", line 61, in create_connection
    for res in socket.getaddrinfo(host, port, family, socket.SOCK_STREAM):
  File "C:\Users\sanpee\AppData\Local\Programs\Python\Python38-32\lib\socket.py", line 918, in getaddrinfo
    for res in _socket.getaddrinfo(host, port, family, type, proto, flags):
socket.gaierror: [Errno 11001] getaddrinfo failed

During handling of the above exception, another exception occurred:

Traceback (most recent call last):
  File "C:\Users\sanpee\AppData\Local\Programs\Python\Python38-32\lib\site-packages\urllib3\connectionpool.py", line 670, in urlopen
    httplib_response = self._make_request(
  File "C:\Users\sanpee\AppData\Local\Programs\Python\Python38-32\lib\site-packages\urllib3\connectionpool.py", line 381, in _make_request
    self._validate_conn(conn)
  File "C:\Users\sanpee\AppData\Local\Programs\Python\Python38-32\lib\site-packages\urllib3\connectionpool.py", line 976, in _validate_conn
    conn.connect()
  File "C:\Users\sanpee\AppData\Local\Programs\Python\Python38-32\lib\site-packages\urllib3\connection.py", line 308, in connect
    conn = self._new_conn()
  File "C:\Users\sanpee\AppData\Local\Programs\Python\Python38-32\lib\site-packages\urllib3\connection.py", line 171, in _new_conn
    raise NewConnectionError(
urllib3.exceptions.NewConnectionError: <urllib3.connection.HTTPSConnection object at 0x053A3B98>: Failed to establish a new connection: [Errno 11001] getaddrinfo failed

During handling of the above exception, another exception occurred:

Traceback (most recent call last):
  File "C:\Users\sanpee\AppData\Local\Programs\Python\Python38-32\lib\site-packages\requests\adapters.py", line 439, in send
    resp = conn.urlopen(
  File "C:\Users\sanpee\AppData\Local\Programs\Python\Python38-32\lib\site-packages\urllib3\connectionpool.py", line 724, in urlopen
    retries = retries.increment(
  File "C:\Users\sanpee\AppData\Local\Programs\Python\Python38-32\lib\site-packages\urllib3\util\retry.py", line 439, in increment
    raise MaxRetryError(_pool, url, error or ResponseError(cause))
urllib3.exceptions.MaxRetryError: HTTPSConnectionPool(host='youtu.be', port=443): Max retries exceeded with url: /wQPgM-9LatM (Caused by NewConnectionError('<urllib3.connection.HTTPSConnection object at 0x053A3B98>: Failed to establish a new connection: [Errno 11001] getaddrinfo failed'))

During handling of the above exception, another exception occurred:

Traceback (most recent call last):
  File "C:\Utilities\Scripts\url-dl-v2\main.py", line 239, in <module>
    parse_input()
  File "C:\Utilities\Scripts\url-dl-v2\main.py", line 122, in parse_input
    Downloader = youtube_extractor(Downloader) #Downloader_2 because Downloader causes errors.
  File "C:\Utilities\Scripts\url-dl-v2\extractors\youtube.py", line 233, in youtube_extractor
    sub_object["video_info"], sub_object["streams"] = extract_video_info(sub_object["id"])
  File "C:\Utilities\Scripts\url-dl-v2\extractors\youtube.py", line 298, in extract_video_info
    test = scrape_yt_link(url)
  File "C:\Utilities\Scripts\url-dl-v2\extractors\youtube.py", line 247, in scrape_yt_link
    response = requests.get(url)
  File "C:\Users\sanpee\AppData\Local\Programs\Python\Python38-32\lib\site-packages\requests\api.py", line 76, in get
    return request('get', url, params=params, **kwargs)
  File "C:\Users\sanpee\AppData\Local\Programs\Python\Python38-32\lib\site-packages\requests\api.py", line 61, in request
    return session.request(method=method, url=url, **kwargs)
  File "C:\Users\sanpee\AppData\Local\Programs\Python\Python38-32\lib\site-packages\requests\sessions.py", line 530, in request
    resp = self.send(prep, **send_kwargs)
  File "C:\Users\sanpee\AppData\Local\Programs\Python\Python38-32\lib\site-packages\requests\sessions.py", line 643, in send
    r = adapter.send(request, **kwargs)
  File "C:\Users\sanpee\AppData\Local\Programs\Python\Python38-32\lib\site-packages\requests\adapters.py", line 516, in send
    raise ConnectionError(e, request=request)
requests.exceptions.ConnectionError: HTTPSConnectionPool(host='youtu.be', port=443): Max retries exceeded with url: /wQPgM-9LatM (Caused by NewConnectionError('<urllib3.connection.HTTPSConnection object at 0x053A3B98>: Failed to establish a new connection: [Errno 11001] getaddrinfo failed'))
2021-03-14 20:31:32,458 - 
Log Ended.
Total time: 0 hrs 0 min 5.03 sec

