2021-03-27 16:28:59,617 - 
Downloading Utility Log. 
Log started.

Move log to Impt Logs if required as only the 10 most recent logs are kept.

2021-03-27 16:29:09,109 - Command: dl -youtube https://www.youtube.com/channel/UCPxHg4192hLDpTI2w7F9rPg
2021-03-27 16:29:09,110 - youtube link
2021-03-27 16:29:09,759 - file_cache is only supported with oauth2client<4.0.0
2021-03-27 16:29:09,819 - Invalid URL 'UUPxHg4192hLDpTI2w7F9rPg': No schema supplied. Perhaps you meant http://UUPxHg4192hLDpTI2w7F9rPg?
Traceback (most recent call last):
  File "c:/Utilities/Scripts/url-dl-v2/main.py", line 240, in <module>
    parse_input()
  File "c:/Utilities/Scripts/url-dl-v2/main.py", line 123, in parse_input
    Downloader = youtube_extractor(Downloader) #Downloader_2 because Downloader causes errors.
  File "c:\Utilities\Scripts\url-dl-v2\extractors\youtube.py", line 216, in youtube_extractor
    for a in extract_from_playlist(uploads):
  File "c:\Utilities\Scripts\url-dl-v2\extractors\youtube.py", line 141, in extract_from_playlist
    list_of_playlist_ids = re.findall(r'(?<=videoId":").{11}',utils.source_code(url))
  File "c:\Utilities\Scripts\url-dl-v2\dl_utils.py", line 37, in source_code
    response = requests.get(link)
  File "C:\Users\sanpee\AppData\Local\Programs\Python\Python38-32\lib\site-packages\requests\api.py", line 76, in get
    return request('get', url, params=params, **kwargs)
  File "C:\Users\sanpee\AppData\Local\Programs\Python\Python38-32\lib\site-packages\requests\api.py", line 61, in request
    return session.request(method=method, url=url, **kwargs)
  File "C:\Users\sanpee\AppData\Local\Programs\Python\Python38-32\lib\site-packages\requests\sessions.py", line 516, in request
    prep = self.prepare_request(req)
  File "C:\Users\sanpee\AppData\Local\Programs\Python\Python38-32\lib\site-packages\requests\sessions.py", line 449, in prepare_request
    p.prepare(
  File "C:\Users\sanpee\AppData\Local\Programs\Python\Python38-32\lib\site-packages\requests\models.py", line 314, in prepare
    self.prepare_url(url, params)
  File "C:\Users\sanpee\AppData\Local\Programs\Python\Python38-32\lib\site-packages\requests\models.py", line 388, in prepare_url
    raise MissingSchema(error)
requests.exceptions.MissingSchema: Invalid URL 'UUPxHg4192hLDpTI2w7F9rPg': No schema supplied. Perhaps you meant http://UUPxHg4192hLDpTI2w7F9rPg?
2021-03-27 16:29:09,823 - 
Log Ended.
Total time: 0 hrs 0 min 10.21 sec

