2021-03-27 13:26:54,539 - 
Downloading Utility Log. 
Log started.

Move log to Impt Logs if required as only the 10 most recent logs are kept.

2021-03-27 13:26:57,119 - Command: dl -youtube https://youtu.be/SeMXa5lBGYc
2021-03-27 13:26:57,120 - youtube link
2021-03-27 13:26:57,668 - Scraping for id: SeMXa5lBGYc
2021-03-27 13:26:58,075 - ! Video (https://youtu.be/SeMXa5lBGYc|Caramelldansen  () Japan 2008 Version (SE)) undownloadable - cipher needed.
2021-03-27 13:26:58,075 - Unable to use main Youtube Extractor, switching to Youtube-dl backend.
2021-03-27 13:26:59,027 - Done downloading audio.
2021-03-27 13:38:35,420 - ERROR: giving up after 0 retries
Traceback (most recent call last):
  File "C:\Utilities\Scripts\url-dl-v2\main.py", line 239, in <module>
    try:
  File "C:\Utilities\Scripts\url-dl-v2\main.py", line 122, in parse_input
    print("Youtube Link. Extractor code may need to be edited if parsing takes too long, may mean a wrong regex because of changed html.")
  File "C:\Utilities\Scripts\url-dl-v2\extractors\youtube.py", line 238, in youtube_extractor
    download_handler(Downloader)
  File "C:\Utilities\Scripts\url-dl-v2\extractors\youtube.py", line 487, in download_handler
    youtube_dl_backup(video_info["url"],root_download_dir)
  File "C:\Utilities\Scripts\url-dl-v2\extractors\youtube.py", line 88, in youtube_dl_backup
    ydl.download([url])
  File "C:\Users\sanpee\AppData\Local\Programs\Python\Python38-32\lib\site-packages\youtube_dl\YoutubeDL.py", line 2055, in download
    res = self.extract_info(
  File "C:\Users\sanpee\AppData\Local\Programs\Python\Python38-32\lib\site-packages\youtube_dl\YoutubeDL.py", line 799, in extract_info
    return self.__extract_info(url, ie, download, extra_info, process)
  File "C:\Users\sanpee\AppData\Local\Programs\Python\Python38-32\lib\site-packages\youtube_dl\YoutubeDL.py", line 806, in wrapper
    return func(self, *args, **kwargs)
  File "C:\Users\sanpee\AppData\Local\Programs\Python\Python38-32\lib\site-packages\youtube_dl\YoutubeDL.py", line 838, in __extract_info
    return self.process_ie_result(ie_result, download, extra_info)
  File "C:\Users\sanpee\AppData\Local\Programs\Python\Python38-32\lib\site-packages\youtube_dl\YoutubeDL.py", line 872, in process_ie_result
    return self.process_video_result(ie_result, download=download)
  File "C:\Users\sanpee\AppData\Local\Programs\Python\Python38-32\lib\site-packages\youtube_dl\YoutubeDL.py", line 1679, in process_video_result
    self.process_info(new_info)
  File "C:\Users\sanpee\AppData\Local\Programs\Python\Python38-32\lib\site-packages\youtube_dl\YoutubeDL.py", line 1963, in process_info
    success = dl(filename, info_dict)
  File "C:\Users\sanpee\AppData\Local\Programs\Python\Python38-32\lib\site-packages\youtube_dl\YoutubeDL.py", line 1902, in dl
    return fd.download(name, info)
  File "C:\Users\sanpee\AppData\Local\Programs\Python\Python38-32\lib\site-packages\youtube_dl\downloader\common.py", line 366, in download
    return self.real_download(filename, info_dict)
  File "C:\Users\sanpee\AppData\Local\Programs\Python\Python38-32\lib\site-packages\youtube_dl\downloader\http.py", line 363, in real_download
    self.report_error('giving up after %s retries' % retries)
  File "C:\Users\sanpee\AppData\Local\Programs\Python\Python38-32\lib\site-packages\youtube_dl\downloader\common.py", line 165, in report_error
    self.ydl.report_error(*args, **kargs)
  File "C:\Users\sanpee\AppData\Local\Programs\Python\Python38-32\lib\site-packages\youtube_dl\YoutubeDL.py", line 628, in report_error
    self.trouble(error_message, tb)
  File "C:\Users\sanpee\AppData\Local\Programs\Python\Python38-32\lib\site-packages\youtube_dl\YoutubeDL.py", line 598, in trouble
    raise DownloadError(message, exc_info)
youtube_dl.utils.DownloadError: ERROR: giving up after 0 retries
2021-03-27 13:38:35,433 - 
Log Ended.
Total time: 0 hrs 11 min 40.90 sec

